2019-08-29 19:32:28,521 ERROR: Exception on / [GET] [in D:\Program Files\Anaconda3\lib\site-packages\flask\app.py:1761]
Traceback (most recent call last):
  File "D:\Program Files\Anaconda3\lib\site-packages\flask\app.py", line 2292, in wsgi_app
    response = self.full_dispatch_request()
  File "D:\Program Files\Anaconda3\lib\site-packages\flask\app.py", line 1815, in full_dispatch_request
    rv = self.handle_user_exception(e)
  File "D:\Program Files\Anaconda3\lib\site-packages\flask\app.py", line 1718, in handle_user_exception
    reraise(exc_type, exc_value, tb)
  File "D:\Program Files\Anaconda3\lib\site-packages\flask\_compat.py", line 35, in reraise
    raise value
  File "D:\Program Files\Anaconda3\lib\site-packages\flask\app.py", line 1813, in full_dispatch_request
    rv = self.dispatch_request()
  File "D:\Program Files\Anaconda3\lib\site-packages\flask\app.py", line 1799, in dispatch_request
    return self.view_functions[rule.endpoint](**req.view_args)
  File "D:\Program Files\Anaconda3\lib\site-packages\flask_login\utils.py", line 261, in decorated_view
    return func(*args, **kwargs)
  File "D:\PythonProject\flask_microblog\app\routes.py", line 58, in index
    prev_url=prev_url)
  File "D:\Program Files\Anaconda3\lib\site-packages\flask\templating.py", line 135, in render_template
    context, ctx.app)
  File "D:\Program Files\Anaconda3\lib\site-packages\flask\templating.py", line 117, in _render
    rv = template.render(context)
  File "D:\Program Files\Anaconda3\lib\site-packages\jinja2\asyncsupport.py", line 76, in render
    return original_render(self, *args, **kwargs)
  File "D:\Program Files\Anaconda3\lib\site-packages\jinja2\environment.py", line 1008, in render
    return self.environment.handle_exception(exc_info, True)
  File "D:\Program Files\Anaconda3\lib\site-packages\jinja2\environment.py", line 780, in handle_exception
    reraise(exc_type, exc_value, tb)
  File "D:\Program Files\Anaconda3\lib\site-packages\jinja2\_compat.py", line 37, in reraise
    raise value.with_traceback(tb)
  File "D:\PythonProject\flask_microblog\app\templates\base.html", line 54, in template
    {% block app_content %}{% endblock %}
  File "D:\Program Files\Anaconda3\lib\site-packages\jinja2\environment.py", line 1005, in render
    return concat(self.root_render_func(self.new_context(vars)))
  File "D:\PythonProject\flask_microblog\app\templates\index.html", line 1, in top-level template code
    {% extends "base.html" %}
  File "D:\Program Files\Anaconda3\lib\site-packages\jinja2\environment.py", line 780, in handle_exception
    reraise(exc_type, exc_value, tb)
  File "D:\Program Files\Anaconda3\lib\site-packages\jinja2\_compat.py", line 37, in reraise
    raise value.with_traceback(tb)
  File "D:\PythonProject\flask_microblog\app\templates\base.html", line 54, in template
    {% block app_content %}{% endblock %}
  File "D:\Program Files\Anaconda3\lib\site-packages\jinja2\environment.py", line 543, in _generate
    optimized=self.optimized)
  File "D:\Program Files\Anaconda3\lib\site-packages\jinja2\compiler.py", line 82, in generate
    generator.visit(node)
  File "D:\Program Files\Anaconda3\lib\site-packages\jinja2\visitor.py", line 38, in visit
    return f(node, *args, **kwargs)
  File "D:\Program Files\Anaconda3\lib\site-packages\jinja2\compiler.py", line 718, in visit_Template
    self.fail('block %r defined twice' % block.name, block.lineno)
  File "D:\Program Files\Anaconda3\lib\site-packages\jinja2\compiler.py", line 315, in fail
    raise TemplateAssertionError(msg, lineno, self.name, self.filename)
jinja2.exceptions.TemplateAssertionError: block 'app_content' defined twice
2019-08-29 19:32:41,953 INFO: Microblog startup [in D:\PythonProject\flask_microblog\app\__init__.py:41]
2019-08-29 19:32:44,833 INFO: Microblog startup [in D:\PythonProject\flask_microblog\app\__init__.py:41]
2019-08-29 19:34:03,603 INFO: Microblog startup [in D:\PythonProject\flask_microblog\app\__init__.py:41]
2019-08-29 19:34:07,252 INFO: Microblog startup [in D:\PythonProject\flask_microblog\app\__init__.py:41]
2019-08-29 19:38:06,951 INFO: Microblog startup [in D:\PythonProject\flask_microblog\app\__init__.py:41]
2019-08-29 19:38:10,712 INFO: Microblog startup [in D:\PythonProject\flask_microblog\app\__init__.py:41]
2019-08-29 19:39:15,934 INFO: Microblog startup [in D:\PythonProject\flask_microblog\app\__init__.py:41]
2019-08-29 19:39:19,946 INFO: Microblog startup [in D:\PythonProject\flask_microblog\app\__init__.py:41]
2019-08-29 19:39:46,728 INFO: Microblog startup [in D:\PythonProject\flask_microblog\app\__init__.py:41]
2019-08-29 19:39:50,639 INFO: Microblog startup [in D:\PythonProject\flask_microblog\app\__init__.py:41]
2019-08-29 19:40:09,801 INFO: Microblog startup [in D:\PythonProject\flask_microblog\app\__init__.py:41]
2019-08-29 19:40:13,080 INFO: Microblog startup [in D:\PythonProject\flask_microblog\app\__init__.py:41]
2019-08-29 19:40:55,760 INFO: Microblog startup [in D:\PythonProject\flask_microblog\app\__init__.py:41]
2019-08-29 19:41:01,439 INFO: Microblog startup [in D:\PythonProject\flask_microblog\app\__init__.py:41]
2019-08-29 19:45:28,381 INFO: Microblog startup [in D:\PythonProject\flask_microblog\app\__init__.py:41]
2019-08-29 19:45:31,561 INFO: Microblog startup [in D:\PythonProject\flask_microblog\app\__init__.py:41]
2019-08-29 19:48:25,588 INFO: Microblog startup [in D:\PythonProject\flask_microblog\app\__init__.py:41]
2019-08-29 19:48:52,734 INFO: Microblog startup [in D:\PythonProject\flask_microblog\app\__init__.py:41]
2019-08-29 19:49:15,970 INFO: Microblog startup [in D:\PythonProject\flask_microblog\app\__init__.py:41]
2019-08-30 10:07:26,714 INFO: Microblog startup [in D:\PythonProject\flask_microblog\app\__init__.py:41]
2019-08-30 10:07:29,623 ERROR: Exception on /login [GET] [in D:\Program Files\Anaconda3\lib\site-packages\flask\app.py:1761]
Traceback (most recent call last):
  File "D:\Program Files\Anaconda3\lib\site-packages\flask\app.py", line 2292, in wsgi_app
    response = self.full_dispatch_request()
  File "D:\Program Files\Anaconda3\lib\site-packages\flask\app.py", line 1815, in full_dispatch_request
    rv = self.handle_user_exception(e)
  File "D:\Program Files\Anaconda3\lib\site-packages\flask\app.py", line 1718, in handle_user_exception
    reraise(exc_type, exc_value, tb)
  File "D:\Program Files\Anaconda3\lib\site-packages\flask\_compat.py", line 35, in reraise
    raise value
  File "D:\Program Files\Anaconda3\lib\site-packages\flask\app.py", line 1813, in full_dispatch_request
    rv = self.dispatch_request()
  File "D:\Program Files\Anaconda3\lib\site-packages\flask\app.py", line 1799, in dispatch_request
    return self.view_functions[rule.endpoint](**req.view_args)
  File "D:\PythonProject\flask_microblog\app\routes.py", line 78, in login
    return render_template('login.html', title='Sign In', form=form)
  File "D:\Program Files\Anaconda3\lib\site-packages\flask\templating.py", line 135, in render_template
    context, ctx.app)
  File "D:\Program Files\Anaconda3\lib\site-packages\flask\templating.py", line 117, in _render
    rv = template.render(context)
  File "D:\Program Files\Anaconda3\lib\site-packages\jinja2\asyncsupport.py", line 76, in render
    return original_render(self, *args, **kwargs)
  File "D:\Program Files\Anaconda3\lib\site-packages\jinja2\environment.py", line 1008, in render
    return self.environment.handle_exception(exc_info, True)
  File "D:\Program Files\Anaconda3\lib\site-packages\jinja2\environment.py", line 780, in handle_exception
    reraise(exc_type, exc_value, tb)
  File "D:\Program Files\Anaconda3\lib\site-packages\jinja2\_compat.py", line 37, in reraise
    raise value.with_traceback(tb)
  File "D:\PythonProject\flask_microblog\app\templates\base.html", line 54, in template
    {% block content %}{% endblock %}
  File "D:\Program Files\Anaconda3\lib\site-packages\jinja2\environment.py", line 1005, in render
    return concat(self.root_render_func(self.new_context(vars)))
  File "D:\PythonProject\flask_microblog\app\templates\login.html", line 1, in top-level template code
    {% extends "base.html" %}
  File "D:\Program Files\Anaconda3\lib\site-packages\jinja2\environment.py", line 780, in handle_exception
    reraise(exc_type, exc_value, tb)
  File "D:\Program Files\Anaconda3\lib\site-packages\jinja2\_compat.py", line 37, in reraise
    raise value.with_traceback(tb)
  File "D:\PythonProject\flask_microblog\app\templates\base.html", line 54, in template
    {% block content %}{% endblock %}
  File "D:\Program Files\Anaconda3\lib\site-packages\jinja2\environment.py", line 543, in _generate
    optimized=self.optimized)
  File "D:\Program Files\Anaconda3\lib\site-packages\jinja2\compiler.py", line 82, in generate
    generator.visit(node)
  File "D:\Program Files\Anaconda3\lib\site-packages\jinja2\visitor.py", line 38, in visit
    return f(node, *args, **kwargs)
  File "D:\Program Files\Anaconda3\lib\site-packages\jinja2\compiler.py", line 718, in visit_Template
    self.fail('block %r defined twice' % block.name, block.lineno)
  File "D:\Program Files\Anaconda3\lib\site-packages\jinja2\compiler.py", line 315, in fail
    raise TemplateAssertionError(msg, lineno, self.name, self.filename)
jinja2.exceptions.TemplateAssertionError: block 'content' defined twice
